<?xml version="1.0" ?>
<!-- =================================================================================== -->
<!-- |    This document was autogenerated by xacro from duaro.urdf.xacro               | -->
<!-- |    EDITING THIS FILE BY HAND IS NOT RECOMMENDED                                 | -->
<!-- =================================================================================== -->
<robot name="khi_duaro" xmlns:controller="http://playerstage.sourceforge.net/gazebo/xmlschema/#controller" xmlns:interface="http://playerstage.sourceforge.net/gazebo/xmlschema/#interface" xmlns:sensor="http://playerstage.sourceforge.net/gazebo/xmlschema/#sensor">
  <transmission name="lower_join1_trans">
    <type>transmission_interface/SimpleTransmission</type>
    <actuator name="lower_joint1_motor">
      <hardwareInterface>hardware_interface/PositionJointInterface</hardwareInterface>
      <mechanicalReduction>1</mechanicalReduction>
    </actuator>
    <joint name="lower_joint1">
      <hardwareInterface>hardware_interface/PositionJointInterface</hardwareInterface>
    </joint>
  </transmission>
  <transmission name="lower_join2_trans">
    <type>transmission_interface/SimpleTransmission</type>
    <actuator name="lower_joint2_motor">
      <hardwareInterface>hardware_interface/PositionJointInterface</hardwareInterface>
      <mechanicalReduction>1</mechanicalReduction>
    </actuator>
    <joint name="lower_joint2">
      <hardwareInterface>hardware_interface/PositionJointInterface</hardwareInterface>
    </joint>
  </transmission>
  <transmission name="lower_join3_trans">
    <type>transmission_interface/SimpleTransmission</type>
    <actuator name="lower_joint3_motor">
      <hardwareInterface>hardware_interface/PositionJointInterface</hardwareInterface>
      <mechanicalReduction>1</mechanicalReduction>
    </actuator>
    <joint name="lower_joint3">
      <hardwareInterface>hardware_interface/PositionJointInterface</hardwareInterface>
    </joint>
  </transmission>
  <transmission name="lower_join4_trans">
    <type>transmission_interface/SimpleTransmission</type>
    <actuator name="lower_joint4_motor">
      <hardwareInterface>hardware_interface/PositionJointInterface</hardwareInterface>
      <mechanicalReduction>1</mechanicalReduction>
    </actuator>
    <joint name="lower_joint4">
      <hardwareInterface>hardware_interface/PositionJointInterface</hardwareInterface>
    </joint>
  </transmission>
  <transmission name="upper_join1_trans">
    <type>transmission_interface/SimpleTransmission</type>
    <actuator name="upper_joint1_motor">
      <hardwareInterface>hardware_interface/PositionJointInterface</hardwareInterface>
      <mechanicalReduction>1</mechanicalReduction>
    </actuator>
    <joint name="upper_joint1">
      <hardwareInterface>hardware_interface/PositionJointInterface</hardwareInterface>
    </joint>
  </transmission>
  <transmission name="upper_join2_trans">
    <type>transmission_interface/SimpleTransmission</type>
    <actuator name="upper_joint2_motor">
      <hardwareInterface>hardware_interface/PositionJointInterface</hardwareInterface>
      <mechanicalReduction>1</mechanicalReduction>
    </actuator>
    <joint name="upper_joint2">
      <hardwareInterface>hardware_interface/PositionJointInterface</hardwareInterface>
    </joint>
  </transmission>
  <transmission name="upper_join3_trans">
    <type>transmission_interface/SimpleTransmission</type>
    <actuator name="upper_joint3_motor">
      <hardwareInterface>hardware_interface/PositionJointInterface</hardwareInterface>
      <mechanicalReduction>1</mechanicalReduction>
    </actuator>
    <joint name="upper_joint3">
      <hardwareInterface>hardware_interface/PositionJointInterface</hardwareInterface>
    </joint>
  </transmission>
  <transmission name="upper_join4_trans">
    <type>transmission_interface/SimpleTransmission</type>
    <actuator name="upper_joint4_motor">
      <hardwareInterface>hardware_interface/PositionJointInterface</hardwareInterface>
      <mechanicalReduction>1</mechanicalReduction>
    </actuator>
    <joint name="upper_joint4">
      <hardwareInterface>hardware_interface/PositionJointInterface</hardwareInterface>
    </joint>
  </transmission>
  <!-- link rviz color-->
  <material name="Light_blue">
    <color rgba="0 1.0 1.0 1.0"/>
  </material>
  <material name="White">
    <color rgba="1.0 1.0 1.0 1.0"/>
  </material>
  <material name="Black">
    <color rgba="0 0 0 1.0"/>
  </material>
  <material name="Red">
    <color rgba="1.0 0 0 1.0"/>
  </material>
  <link name="duarobase_link">
    <visual>
      <geometry>
        <mesh filename="package://khi_duaro_description/meshes/WD002N_F502_Adjuster_pad.stl"/>
      </geometry>
      <material name="White"/>
      <origin rpy="0 0 0" xyz="0 0 0"/>
    </visual>
    <collision>
      <geometry>
        <mesh filename="package://khi_duaro_description/meshes/WD002N_F502_Adjuster_pad.stl"/>
      </geometry>
      <material name="White"/>
      <origin rpy="0 0 0" xyz="0 0 0"/>
    </collision>
  </link>
  <link name="duaroduaro_body">
    <visual>
      <geometry>
        <mesh filename="package://khi_duaro_description/meshes/WD002N_F502_Cabinet_body.stl"/>
      </geometry>
      <material name="White"/>
      <origin rpy="0 0 0" xyz="0 0 0"/>
    </visual>
    <collision>
      <geometry>
        <mesh filename="package://khi_duaro_description/meshes/WD002N_F502_Cabinet_body.stl"/>
      </geometry>
      <origin rpy="0 0 0" xyz="0 0 0"/>
    </collision>
    <inertial>
      <mass value="100"/>
      <inertia ixx="1.0" ixy="0.0" ixz="0.0" iyy="1.0" iyz="0.0" izz="1.0"/>
    </inertial>
  </link>
  <joint name="duaroduaro_body_joint" type="fixed">
    <parent link="duarobase_link"/>
    <child link="duaroduaro_body"/>
    <origin rpy="0 0 0" xyz="0 0 0"/>
  </joint>
  <link name="duaroduaro_j0_cover">
    <visual>
      <geometry>
        <mesh filename="package://khi_duaro_description/meshes/WD002N_A201_j0_cover_Ver2m.stl"/>
      </geometry>
      <material name="Light_blue"/>
      <origin rpy="0 0 0" xyz="0 0 0"/>
    </visual>
    <collision>
      <geometry>
        <mesh filename="package://khi_duaro_description/meshes/WD002N_A201_j0_cover_Ver2m.stl"/>
      </geometry>
      <origin rpy="0 0 0" xyz="0 0 0"/>
    </collision>
    <inertial>
      <mass value="2"/>
      <inertia ixx="1.0" ixy="0.0" ixz="0.0" iyy="1.0" iyz="0.0" izz="1.0"/>
    </inertial>
  </link>
  <joint name="duaroduaro_j0_cover_joint" type="fixed">
    <parent link="duarobase_link"/>
    <child link="duaroduaro_j0_cover"/>
    <origin rpy="0 0 0" xyz="0 0 0.82"/>
  </joint>
  <link name="duaroduaro_logo">
    <visual>
      <geometry>
        <mesh filename="package://khi_duaro_description/meshes/WD002N_F502_LOGO_duAro.stl"/>
      </geometry>
      <material name="Black"/>
      <origin rpy="0 0 0" xyz="0 0 0"/>
    </visual>
    <collision>
      <geometry>
        <mesh filename="package://khi_duaro_description/meshes/WD002N_F502_LOGO_duAro.stl"/>
      </geometry>
      <origin rpy="0 0 0" xyz="0 0 0"/>
    </collision>
    <inertial>
      <mass value="1"/>
      <inertia ixx="1.0" ixy="0.0" ixz="0.0" iyy="1.0" iyz="0.0" izz="1.0"/>
    </inertial>
  </link>
  <joint name="duaroduaro_logo_joint" type="fixed">
    <parent link="duarobase_link"/>
    <child link="duaroduaro_logo"/>
    <origin rpy="0 0 0" xyz="0 0 0"/>
  </joint>
  <link name="duarokawasaki_logo">
    <visual>
      <geometry>
        <mesh filename="package://khi_duaro_description/meshes/WD002N_F502_LOGO_Kawasaki.stl"/>
      </geometry>
      <material name="Red"/>
      <origin rpy="0 0 0" xyz="0 0 0"/>
    </visual>
    <collision>
      <geometry>
        <mesh filename="package://khi_duaro_description/meshes/WD002N_F502_LOGO_Kawasaki.stl"/>
      </geometry>
      <origin rpy="0 0 0" xyz="0 0 0"/>
    </collision>
    <inertial>
      <mass value="1"/>
      <inertia ixx="1.0" ixy="0.0" ixz="0.0" iyy="1.0" iyz="0.0" izz="1.0"/>
    </inertial>
  </link>
  <joint name="duarokawasaki_logo_joint" type="fixed">
    <parent link="duarobase_link"/>
    <child link="duarokawasaki_logo"/>
    <origin rpy="0 0 0" xyz="0 0 0"/>
  </joint>
  <link name="duaroduaro_body_cover">
    <visual>
      <geometry>
        <mesh filename="package://khi_duaro_description/meshes/WD002N_F502_Cabinet_front_cover.stl"/>
      </geometry>
      <material name="Light_blue"/>
      <origin rpy="0 0 0" xyz="0 0 0"/>
    </visual>
    <collision>
      <geometry>
        <mesh filename="package://khi_duaro_description/meshes/WD002N_F502_Cabinet_front_cover.stl"/>
      </geometry>
      <origin rpy="0 0 0" xyz="0 0 0"/>
    </collision>
    <inertial>
      <mass value="1"/>
      <inertia ixx="1.0" ixy="0.0" ixz="0.0" iyy="1.0" iyz="0.0" izz="1.0"/>
    </inertial>
  </link>
  <joint name="duaroduaro_body_cover_joint" type="fixed">
    <parent link="duarobase_link"/>
    <child link="duaroduaro_body_cover"/>
    <origin rpy="0 0 0" xyz="0 0 0"/>
  </joint>
  <link name="duarocart">
    <visual>
      <geometry>
        <mesh filename="package://khi_duaro_description/meshes/WD002N_F502_Cart.stl"/>
      </geometry>
      <material name="White"/>
      <origin rpy="0 0 0" xyz="0 0 0"/>
    </visual>
    <collision>
      <geometry>
        <mesh filename="package://khi_duaro_description/meshes/WD002N_F502_Cart.stl"/>
      </geometry>
      <origin rpy="0 0 0" xyz="0 0 0"/>
    </collision>
    <inertial>
      <mass value="2"/>
      <inertia ixx="1.0" ixy="0.0" ixz="0.0" iyy="1.0" iyz="0.0" izz="1.0"/>
    </inertial>
  </link>
  <joint name="duarocart_joint" type="fixed">
    <parent link="duarobase_link"/>
    <child link="duarocart"/>
    <origin rpy="0 0 0" xyz="0 0 0"/>
  </joint>
  <link name="duaroduaro_j0">
    <visual>
      <geometry>
        <mesh filename="package://khi_duaro_description/meshes/WD002N_A201_j0_Ver2m.stl"/>
      </geometry>
      <material name="White"/>
      <origin rpy="0 0 0" xyz="0 0 0"/>
    </visual>
    <collision>
      <geometry>
        <mesh filename="package://khi_duaro_description/meshes/WD002N_A201_j0_Ver2m.stl"/>
      </geometry>
      <origin rpy="0 0 0" xyz="0 0 0"/>
    </collision>
    <inertial>
      <mass value="10"/>
      <inertia ixx="1.0" ixy="0.0" ixz="0.0" iyy="1.0" iyz="0.0" izz="1.0"/>
    </inertial>
  </link>
  <joint name="duarojoint0" type="fixed">
    <origin xyz="0 0 0.82"/>
    <parent link="duaroduaro_body"/>
    <child link="duaroduaro_j0"/>
  </joint>
  <!-- lower arm -->
  <link name="duarolower_link_j1">
    <visual>
      <geometry>
        <mesh filename="package://khi_duaro_description/meshes/WD002N_A201L_J1_Ver2m.stl"/>
      </geometry>
      <material name="White"/>
      <origin rpy="0 0 0" xyz="0 0 0"/>
    </visual>
    <collision>
      <geometry>
        <mesh filename="package://khi_duaro_description/meshes/WD002N_A201L_J1_Ver2m.stl"/>
      </geometry>
      <material name="White"/>
      <origin rpy="0 0 0" xyz="0 0 0"/>
    </collision>
    <inertial>
      <mass value="11.463"/>
      <inertia ixx="1.0" ixy="0.0" ixz="0.0" iyy="1.0" iyz="0.0" izz="0.806914299802127"/>
    </inertial>
  </link>
  <joint name="duarolower_joint1" type="revolute">
    <axis rpy="0 0 0" xyz="0 0 1"/>
    <limit effort="100.0" lower="-2.9670597283903604" upper="2.9670597283903604" velocity="4.1887902047863905"/>
    <origin rpy="0 0 0" xyz="0 0 0.2515"/>
    <parent link="duaroduaro_j0"/>
    <child link="duarolower_link_j1"/>
    <dynamics damping="0.0" friction="0.0"/>
  </joint>
  <link name="duarolower_link_j2">
    <visual>
      <geometry>
        <mesh filename="package://khi_duaro_description/meshes/WD002N_A202L_J2m.stl"/>
      </geometry>
      <material name="White"/>
      <origin rpy="0 0 0" xyz="0 0 0"/>
    </visual>
    <collision>
      <geometry>
        <mesh filename="package://khi_duaro_description/meshes/WD002N_A202L_J2m.stl"/>
      </geometry>
      <material name="White"/>
      <origin rpy="0 0 0" xyz="0 0 0"/>
    </collision>
    <inertial>
      <mass value="3.747"/>
      <inertia ixx="1.0" ixy="0.0" ixz="0.0" iyy="1.0" iyz="0.0" izz="0.167113962990643"/>
    </inertial>
  </link>
  <joint name="duarolower_joint2" type="revolute">
    <axis rpy="0 0 0" xyz="0 0 1"/>
    <limit effort="100.0" lower="-2.443460952792061" upper="2.443460952792061" velocity="5.497787143782138"/>
    <origin xyz="0 0.36 0.0905"/>
    <parent link="duarolower_link_j1"/>
    <child link="duarolower_link_j2"/>
    <dynamics damping="0.0" friction="0.0"/>
  </joint>
  <link name="duarolower_link_j3">
    <visual>
      <geometry>
        <mesh filename="package://khi_duaro_description/meshes/WD002N_A202L_J3m.stl"/>
      </geometry>
      <material name="White"/>
      <origin rpy="0 0 0" xyz="0 0 0"/>
    </visual>
    <collision>
      <geometry>
        <mesh filename="package://khi_duaro_description/meshes/WD002N_A202L_J3m.stl"/>
      </geometry>
      <material name="White"/>
      <origin rpy="0 0 0" xyz="0 0 0"/>
    </collision>
    <inertial>
      <mass value="3.476"/>
      <inertia ixx="1.0" ixy="0.0" ixz="0.0" iyy="1.0" iyz="0.0" izz="1.0"/>
    </inertial>
  </link>
  <joint name="duarolower_joint3" type="prismatic">
    <axis rpy="0 0 0" xyz="0 0 1"/>
    <limit effort="100.0" lower="0" upper="0.15" velocity="0.3"/>
    <origin xyz="0 0.4 0.03850"/>
    <parent link="duarolower_link_j2"/>
    <child link="duarolower_link_j3"/>
  </joint>
  <link name="duarolower_link_j3_obst">
    <visual>
      <geometry>
        <mesh filename="package://khi_duaro_description/meshes/WD002N_A202L_J3_obstaclem.stl"/>
      </geometry>
      <material name="Black"/>
      <origin rpy="0 0 0" xyz="0 0 0"/>
    </visual>
  </link>
  <joint name="duarolower_j3_obstaclem_joint" type="fixed">
    <origin rpy="0 0 0" xyz="0 0 0"/>
    <parent link="duarolower_link_j3"/>
    <child link="duarolower_link_j3_obst"/>
  </joint>
  <link name="duarolower_link_j4">
    <visual>
      <geometry>
        <mesh filename="package://khi_duaro_description/meshes/WD002N_A202L_J4m.stl"/>
      </geometry>
      <material name=""/>
      <origin rpy="0 0 0" xyz="0 0 0"/>
    </visual>
    <collision>
      <geometry>
        <mesh filename="package://khi_duaro_description/meshes/WD002N_A202L_J4m.stl"/>
      </geometry>
      <material name="White"/>
      <origin rpy="0 0 0" xyz="0 0 0"/>
    </collision>
    <inertial>
      <mass value="0.5"/>
      <inertia ixx="1.0" ixy="0.0" ixz="0.0" iyy="1.0" iyz="0.0" izz="1.0"/>
    </inertial>
  </link>
  <joint name="duarolower_joint4" type="revolute">
    <axis rpy="0 0 0" xyz="0 0 1"/>
    <limit effort="100.0" lower="-6.283185307179586" upper="6.283185307179586" velocity="10.471975511965978"/>
    <origin xyz="0 0 -0.24"/>
    <parent link="duarolower_link_j3"/>
    <child link="duarolower_link_j4"/>
    <dynamics damping="0.0" friction="0.0"/>
  </joint>
  <!-- upper arm -->
  <link name="duaroupper_link_j1">
    <visual>
      <geometry>
        <mesh filename="package://khi_duaro_description/meshes/WD002N_A201U_J1_Ver2m.stl"/>
      </geometry>
      <material name="White"/>
      <origin xyz="0 0 0"/>
    </visual>
    <collision>
      <geometry>
        <mesh filename="package://khi_duaro_description/meshes/WD002N_A201U_J1_Ver2m.stl"/>
      </geometry>
      <material name="White"/>
      <origin rpy="0 0 0" xyz="0 0 0"/>
    </collision>
    <inertial>
      <mass value="11.452"/>
      <inertia ixx="1.0" ixy="0.0" ixz="0.0" iyy="1.0" iyz="0.0" izz="0.8539434419510881"/>
    </inertial>
  </link>
  <joint name="duaroupper_joint1" type="revolute">
    <origin rpy="0 0 0" xyz="0 0 0.3805"/>
    <axis rpy="0 0 0" xyz="0 0 1"/>
    <limit effort="100.0" lower="-2.443460952792061" upper="8.726646259971648" velocity="4.1887902047863905"/>
    <parent link="duaroduaro_j0"/>
    <child link="duaroupper_link_j1"/>
    <dynamics damping="0.0" friction="0.0"/>
  </joint>
  <link name="duaroupper_link_j2">
    <visual>
      <geometry>
        <mesh filename="package://khi_duaro_description/meshes/WD002N_A202U_J2m.stl"/>
      </geometry>
      <material name="White"/>
      <origin rpy="0 0 0" xyz="0 0 0"/>
    </visual>
    <collision>
      <geometry>
        <mesh filename="package://khi_duaro_description/meshes/WD002N_A202U_J2m.stl"/>
      </geometry>
      <material name="White"/>
      <origin rpy="0 0 0" xyz="0 0 0"/>
    </collision>
    <inertial>
      <mass value="3.751"/>
      <inertia ixx="1.0" ixy="0.0" ixz="0.0" iyy="1.0" iyz="0.0" izz="0.167279751763904"/>
    </inertial>
  </link>
  <joint name="duaroupper_joint2" type="revolute">
    <axis rpy="0 0 0" xyz="0 0 1"/>
    <limit effort="100.0" lower="-2.443460952792061" upper="2.443460952792061" velocity="5.497787143782138"/>
    <origin xyz="0 0.36 0"/>
    <parent link="duaroupper_link_j1"/>
    <child link="duaroupper_link_j2"/>
    <dynamics damping="0.0" friction="0.0"/>
  </joint>
  <link name="duaroupper_link_j3">
    <visual>
      <geometry>
        <mesh filename="package://khi_duaro_description/meshes/WD002N_A202U_J3m.stl"/>
      </geometry>
      <material name="White"/>
      <origin rpy="0 0 0" xyz="0 0 0"/>
    </visual>
    <collision>
      <geometry>
        <mesh filename="package://khi_duaro_description/meshes/WD002N_A202U_J3m.stl"/>
      </geometry>
      <material name="White"/>
      <origin rpy="0 0 0" xyz="0 0 0"/>
    </collision>
    <inertial>
      <mass value="3.476"/>
      <inertia ixx="1.0" ixy="0.0" ixz="0.0" iyy="1.0" iyz="0.0" izz="1.0"/>
    </inertial>
  </link>
  <joint name="duaroupper_joint3" type="prismatic">
    <axis rpy="0 0 0" xyz="0 0 1"/>
    <limit effort="100.0" lower="0" upper="0.15" velocity="0.3"/>
    <origin xyz="0 0.4 0"/>
    <parent link="duaroupper_link_j2"/>
    <child link="duaroupper_link_j3"/>
  </joint>
  <link name="duaroupper_link_j3_obst">
    <visual>
      <geometry>
        <mesh filename="package://khi_duaro_description/meshes/WD002N_A202U_J3_obstaclem.stl"/>
      </geometry>
      <material name="Black"/>
      <origin rpy="0 0 0" xyz="0 0 0"/>
    </visual>
  </link>
  <joint name="duaroupper_j3_obstaclem_joint" type="fixed">
    <origin xyz="0 0 0"/>
    <parent link="duaroupper_link_j3"/>
    <child link="duaroupper_link_j3_obst"/>
  </joint>
  <link name="duaroupper_link_j4">
    <visual>
      <geometry>
        <mesh filename="package://khi_duaro_description/meshes/WD002N_A202U_J4m.stl"/>
      </geometry>
      <material name=""/>
      <origin rpy="0 0 0" xyz="0 0 0"/>
    </visual>
    <collision>
      <geometry>
        <mesh filename="package://khi_duaro_description/meshes/WD002N_A202U_J4m.stl"/>
      </geometry>
      <material name="White"/>
      <origin rpy="0 0 0" xyz="0 0 0"/>
    </collision>
    <inertial>
      <mass value="10"/>
      <inertia ixx="1.0" ixy="0.0" ixz="0.0" iyy="1.0" iyz="0.0" izz="1.0"/>
    </inertial>
  </link>
  <joint name="duaroupper_joint4" type="revolute">
    <axis rpy="0 0 0" xyz="0 0 1"/>
    <limit effort="100.0" lower="-6.283185307179586" upper="6.283185307179586" velocity="0.3"/>
    <origin xyz="0 0 -0.24"/>
    <parent link="duaroupper_link_j3"/>
    <child link="duaroupper_link_j4"/>
    <dynamics damping="0.0" friction="0.0"/>
  </joint>
  <gazebo reference="duaroduaro_body">
    <material>Gazebo/White</material>
  </gazebo>
  <gazebo reference="duaropedestal_obstacle">
    <material>Gazebo/Light_blue</material>
  </gazebo>
  <gazebo reference="duaroduaro_logo">
    <material>Gazebo/Black</material>
  </gazebo>
  <gazebo reference="duarobase_link">
    <material>Gazebo/White</material>
  </gazebo>
  <gazebo reference="duaroduaro_j0">
    <material>Gazebo/White</material>
  </gazebo>
  <gazebo reference="duaroduaro_j0_cover">
    <material>Gazebo/Light_blue</material>
  </gazebo>
  <gazebo reference="duarolower_link_j1">
    <material>Gazebo/White</material>
  </gazebo>
  <gazebo reference="duarolower_link_j2">
    <material>Gazebo/White</material>
  </gazebo>
  <gazebo reference="duarolower_link_j3">
    <material>Gazebo/White</material>
  </gazebo>
  <gazebo reference="duarolower_link_j4">
    <material>Gazebo/White</material>
  </gazebo>
  <gazebo reference="duarolower_link_j3_obst">
    <material>Gazebo/Black</material>
  </gazebo>
  <gazebo reference="duaroupper_link_j1">
    <material>Gazebo/White</material>
  </gazebo>
  <gazebo reference="duaroupper_link_j2">
    <material>Gazebo/White</material>
  </gazebo>
  <gazebo reference="duaroupper_link_j3">
    <material>Gazebo/White</material>
  </gazebo>
  <gazebo reference="duaroupper_link_j4">
    <material>Gazebo/White</material>
  </gazebo>
  <gazebo reference="duaroupper_link_j3_obst">
    <material>Gazebo/Black</material>
  </gazebo>
  <gazebo reference="duaroduaro_body">
    <material>Gazebo/White</material>
  </gazebo>
  <!-- duaro end -->
  <gazebo>
    <plugin filename="libgazebo_ros_control.so" name="gazebo_ros_control">
      <robotNamespace>/</robotNamespace>
    </plugin>
  </gazebo>
  <joint name="lower_gripper_anterior_gripper_joint" type="fixed">
    <insert_block name="origin"/>
    <parent link="duarolower_link_j4"/>
    <child link="lower_gripper_base_link"/>
  </joint>
  <!-- BASE LINK -->
  <link name="lower_gripper_base_link">
    <inertial>
      <mass value="0.25"/>
      <origin xyz="0 0 0"/>
      <!--inertia ixx="1.0" ixy="0.0" ixz="0.0"
               iyy="100.0" iyz="0.0" 
               izz="1.0" /-->
      <inertia ixx="1.0" ixy="0.0" ixz="0.0" iyy="1.0" iyz="0.0" izz="1.0"/>
    </inertial>
    <visual>
      <origin rpy="3.14 0 0" xyz="0.0 0 0"/>
      <geometry>
        <mesh filename="package://wsg_50_simulation/meshes/WSG50_110.stl" scale="1 1 1"/>
        <!--box size="0.146 0.05 0.0735"/-->
      </geometry>
      <material name="grey">
        <color rgba="0.5 0.5 0.5 1"/>
      </material>
    </visual>
    <collision>
      <origin rpy="3.14 0 0" xyz="0.0 0 0"/>
      <geometry>
        <!--box size="0.146 0.05 0.0735"/-->
        <mesh filename="package://wsg_50_simulation/meshes/WSG50_110.stl" scale="1 1 1"/>
      </geometry>
    </collision>
  </link>
  <gazebo reference="lower_gripper_base_link">
    <material>Gazebo/Grey</material>
    <turnGravityOff>false</turnGravityOff>
  </gazebo>
  <joint name="lower_gripper_center_joint" type="fixed">
    <origin rpy="0 0 0" xyz="0 0 -0.017"/>
    <!--origin xyz="-0.0067 0 0.049" rpy="0 0 0" /-->
    <parent link="lower_gripper_base_link"/>
    <child link="lower_gripper_center"/>
  </joint>
  <link name="lower_gripper_center">
  </link>
  <!-- GRIPPER LEFT -->
  <joint name="lower_gripper_finger_left_joint" type="prismatic">
    <limit effort="1.0" lower="-0.055" upper="-0.0027" velocity="1.0"/>
    <origin rpy="0 0 0" xyz="0 0 0"/>
    <!--origin xyz="-0.0067 0 0.049" rpy="0 0 0" /-->
    <parent link="lower_gripper_base_link"/>
    <child link="lower_gripper_gripper_left"/>
    <dynamics damping="100" friction="100"/>
    <axis xyz="1 0 0"/>
    <limit effort="100" velocity="100"/>
  </joint>
  <transmission name="lower_gripper_base_trans_left" type="pr2_mechanism_model/SimpleTransmission">
    <actuator name="lower_gripper_base_motor_left"/>
    <joint name="lower_gripper_base_joint_gripper_left"/>
    <mechanicalReduction>1</mechanicalReduction>
    <motorTorqueConstant>1</motorTorqueConstant>
  </transmission>
  <link name="lower_gripper_gripper_left">
    <inertial>
      <mass value="0.1"/>
      <origin xyz="0 0 0"/>
      <inertia ixx="1.0" ixy="0.0" ixz="0.0" iyy="1.0" iyz="0.0" izz="1.0"/>
    </inertial>
    <visual>
      <origin rpy="3.14 0 0" xyz="0.0 0 0"/>
      <geometry>
        <mesh filename="package://wsg_50_simulation/meshes/GUIDE_WSG50_110.stl" scale="0.001 0.001 0.001"/>
        <!--box size="0.0175 0.03 0.024"/-->
      </geometry>
      <material name="black">
        <color rgba="0 0 0 1"/>
      </material>
    </visual>
    <collision>
      <origin rpy="3.14 0 0" xyz="0 0 0"/>
      <geometry>
        <!--box size="0.0175 0.03 0.024"/-->
        <mesh filename="package://wsg_50_simulation/meshes/GUIDE_WSG50_110.stl" scale="0.001 0.001 0.001"/>
      </geometry>
    </collision>
    <contact_coefficients kd="1.0" kp="1000.0" mu="0"/>
  </link>
  <gazebo reference="lower_gripper_gripper_left">
    <material>Gazebo/Blue</material>
    <turnGravityOff>false</turnGravityOff>
  </gazebo>
  <!-- LEFT FINGER -->
  <joint name="lower_gripper_guide_joint_finger_left" type="fixed">
    <origin rpy="0 0 0" xyz="0 0 -0.017"/>
    <parent link="lower_gripper_gripper_left"/>
    <child link="lower_gripper_finger_left"/>
    <dynamics damping="100" friction="100"/>
    <axis xyz="1 0 0"/>
    <limit effort="100" velocity="100"/>
  </joint>
  <link name="lower_gripper_finger_left">
    <inertial>
      <mass value="0.1"/>
      <origin xyz="0 0 0"/>
      <inertia ixx="1.0" ixy="0.0" ixz="0.0" iyy="1.0" iyz="0.0" izz="1.0"/>
    </inertial>
    <visual>
      <origin rpy="3.14 0 0" xyz="0.0 0 0"/>
      <geometry>
        <mesh filename="package://wsg_50_simulation/meshes/WSG-FMF.stl" scale="0.001 0.001 0.001"/>
      </geometry>
      <material name="black">
        <color rgba="0 0 0 1"/>
      </material>
    </visual>
    <collision>
      <origin rpy="3.14 0 0" xyz="0 0 0"/>
      <geometry>
        <mesh filename="package://wsg_50_simulation/meshes/WSG-FMF.stl" scale="0.001 0.001 0.001"/>
      </geometry>
    </collision>
    <contact_coefficients kd="1.0" kp="1000.0" mu="0"/>
  </link>
  <gazebo reference="lower_gripper_finger_left">
    <material>Gazebo/Blue</material>
    <turnGravityOff>false</turnGravityOff>
  </gazebo>
  <!-- GRIPPER RIGHT -->
  <joint name="lower_gripper_finger_right_joint" type="prismatic">
    <limit effort="1.0" lower="0.0027" upper="0.055" velocity="1.0"/>
    <origin rpy="0 0 3.14159" xyz="0 0 0"/>
    <parent link="lower_gripper_base_link"/>
    <child link="lower_gripper_gripper_right"/>
    <axis xyz="-1 0 0"/>
    <dynamics damping="100" friction="100"/>
    <limit effort="100" velocity="100"/>
  </joint>
  <transmission name="lower_gripper_base_trans_right" type="pr2_mechanism_model/SimpleTransmission">
    <actuator name="lower_gripper_base_motor_right"/>
    <joint name="lower_gripper_base_joint_gripper_right"/>
    <mechanicalReduction>1</mechanicalReduction>
    <motorTorqueConstant>1</motorTorqueConstant>
  </transmission>
  <link name="lower_gripper_gripper_right">
    <inertial>
      <mass value="0.1"/>
      <origin xyz="0 0 0"/>
      <inertia ixx="1.0" ixy="0.0" ixz="0.0" iyy="1.0" iyz="0.0" izz="1.0"/>
    </inertial>
    <visual>
      <origin rpy="3.14 0 0" xyz="0.0 0 0"/>
      <geometry>
        <mesh filename="package://wsg_50_simulation/meshes/GUIDE_WSG50_110.stl" scale="0.001 0.001 0.001"/>
        <!--box size="0.0175 0.03 0.024"/-->
      </geometry>
      <material name="black">
        <color rgba="0 0 0 1"/>
      </material>
    </visual>
    <collision>
      <origin rpy="3.14 0 0" xyz="0 0 0"/>
      <geometry>
        <!--box size="0.0175 0.03 0.024"/-->
        <mesh filename="package://wsg_50_simulation/meshes/GUIDE_WSG50_110.stl" scale="0.001 0.001 0.001"/>
      </geometry>
    </collision>
    <contact_coefficients kd="1.0" kp="1000.0" mu="0"/>
  </link>
  <gazebo reference="gripper_right">
    <material>Gazebo/White</material>
    <turnGravityOff>false</turnGravityOff>
  </gazebo>
  <!-- RIGHT FINGER -->
  <joint name="lower_gripper_guide_joint_finger_right" type="fixed">
    <origin rpy="0 0 0" xyz="0 0 -0.017"/>
    <parent link="lower_gripper_gripper_right"/>
    <child link="lower_gripper_finger_right"/>
    <dynamics damping="100" friction="100"/>
    <axis xyz="1 0 0"/>
    <limit effort="100" velocity="100"/>
  </joint>
  <link name="lower_gripper_finger_right">
    <inertial>
      <mass value="0.1"/>
      <origin xyz="0 0 0"/>
      <inertia ixx="1.0" ixy="0.0" ixz="0.0" iyy="1.0" iyz="0.0" izz="1.0"/>
    </inertial>
    <visual>
      <origin rpy="3.14 0 0" xyz="0.0 0 0"/>
      <geometry>
        <mesh filename="package://wsg_50_simulation/meshes/WSG-FMF.stl" scale="0.001 0.001 0.001"/>
      </geometry>
      <material name="black">
        <color rgba="0 0 0 1"/>
      </material>
    </visual>
    <collision>
      <origin rpy="3.14 0 0" xyz="0 0 0"/>
      <geometry>
        <mesh filename="package://wsg_50_simulation/meshes/WSG-FMF.stl" scale="0.001 0.001 0.001"/>
      </geometry>
    </collision>
    <contact_coefficients kd="1.0" kp="1000.0" mu="0"/>
  </link>
  <gazebo reference="lower_gripper_finger_right">
    <material>Gazebo/White</material>
    <turnGravityOff>false</turnGravityOff>
  </gazebo>
  <joint name="upper_gripper_anterior_gripper_joint" type="fixed">
    <insert_block name="origin"/>
    <parent link="duaroupper_link_j4"/>
    <child link="upper_gripper_base_link"/>
  </joint>
  <!-- BASE LINK -->
  <link name="upper_gripper_base_link">
    <inertial>
      <mass value="0.25"/>
      <origin xyz="0 0 0"/>
      <!--inertia ixx="1.0" ixy="0.0" ixz="0.0"
               iyy="100.0" iyz="0.0" 
               izz="1.0" /-->
      <inertia ixx="1.0" ixy="0.0" ixz="0.0" iyy="1.0" iyz="0.0" izz="1.0"/>
    </inertial>
    <visual>
      <origin rpy="3.14 0 0" xyz="0.0 0 0"/>
      <geometry>
        <mesh filename="package://wsg_50_simulation/meshes/WSG50_110.stl" scale="1 1 1"/>
        <!--box size="0.146 0.05 0.0735"/-->
      </geometry>
      <material name="grey">
        <color rgba="0.5 0.5 0.5 1"/>
      </material>
    </visual>
    <collision>
      <origin rpy="3.14 0 0" xyz="0.0 0 0"/>
      <geometry>
        <!--box size="0.146 0.05 0.0735"/-->
        <mesh filename="package://wsg_50_simulation/meshes/WSG50_110.stl" scale="1 1 1"/>
      </geometry>
    </collision>
  </link>
  <gazebo reference="upper_gripper_base_link">
    <material>Gazebo/Grey</material>
    <turnGravityOff>false</turnGravityOff>
  </gazebo>
  <joint name="upper_gripper_center_joint" type="fixed">
    <origin rpy="0 0 0" xyz="0 0 -0.017"/>
    <!--origin xyz="-0.0067 0 0.049" rpy="0 0 0" /-->
    <parent link="upper_gripper_base_link"/>
    <child link="upper_gripper_center"/>
  </joint>
  <link name="upper_gripper_center">
  </link>
  <!-- GRIPPER LEFT -->
  <joint name="upper_gripper_finger_left_joint" type="prismatic">
    <limit effort="1.0" lower="-0.055" upper="-0.0027" velocity="1.0"/>
    <origin rpy="0 0 0" xyz="0 0 0"/>
    <!--origin xyz="-0.0067 0 0.049" rpy="0 0 0" /-->
    <parent link="upper_gripper_base_link"/>
    <child link="upper_gripper_gripper_left"/>
    <dynamics damping="100" friction="100"/>
    <axis xyz="1 0 0"/>
    <limit effort="100" velocity="100"/>
  </joint>
  <transmission name="upper_gripper_base_trans_left" type="pr2_mechanism_model/SimpleTransmission">
    <actuator name="upper_gripper_base_motor_left"/>
    <joint name="upper_gripper_base_joint_gripper_left"/>
    <mechanicalReduction>1</mechanicalReduction>
    <motorTorqueConstant>1</motorTorqueConstant>
  </transmission>
  <link name="upper_gripper_gripper_left">
    <inertial>
      <mass value="0.1"/>
      <origin xyz="0 0 0"/>
      <inertia ixx="1.0" ixy="0.0" ixz="0.0" iyy="1.0" iyz="0.0" izz="1.0"/>
    </inertial>
    <visual>
      <origin rpy="3.14 0 0" xyz="0.0 0 0"/>
      <geometry>
        <mesh filename="package://wsg_50_simulation/meshes/GUIDE_WSG50_110.stl" scale="0.001 0.001 0.001"/>
        <!--box size="0.0175 0.03 0.024"/-->
      </geometry>
      <material name="black">
        <color rgba="0 0 0 1"/>
      </material>
    </visual>
    <collision>
      <origin rpy="3.14 0 0" xyz="0 0 0"/>
      <geometry>
        <!--box size="0.0175 0.03 0.024"/-->
        <mesh filename="package://wsg_50_simulation/meshes/GUIDE_WSG50_110.stl" scale="0.001 0.001 0.001"/>
      </geometry>
    </collision>
    <contact_coefficients kd="1.0" kp="1000.0" mu="0"/>
  </link>
  <gazebo reference="upper_gripper_gripper_left">
    <material>Gazebo/Blue</material>
    <turnGravityOff>false</turnGravityOff>
  </gazebo>
  <!-- LEFT FINGER -->
  <joint name="upper_gripper_guide_joint_finger_left" type="fixed">
    <origin rpy="0 0 0" xyz="0 0 -0.017"/>
    <parent link="upper_gripper_gripper_left"/>
    <child link="upper_gripper_finger_left"/>
    <dynamics damping="100" friction="100"/>
    <axis xyz="1 0 0"/>
    <limit effort="100" velocity="100"/>
  </joint>
  <link name="upper_gripper_finger_left">
    <inertial>
      <mass value="0.1"/>
      <origin xyz="0 0 0"/>
      <inertia ixx="1.0" ixy="0.0" ixz="0.0" iyy="1.0" iyz="0.0" izz="1.0"/>
    </inertial>
    <visual>
      <origin rpy="3.14 0 0" xyz="0.0 0 0"/>
      <geometry>
        <mesh filename="package://wsg_50_simulation/meshes/WSG-FMF.stl" scale="0.001 0.001 0.001"/>
      </geometry>
      <material name="black">
        <color rgba="0 0 0 1"/>
      </material>
    </visual>
    <collision>
      <origin rpy="3.14 0 0" xyz="0 0 0"/>
      <geometry>
        <mesh filename="package://wsg_50_simulation/meshes/WSG-FMF.stl" scale="0.001 0.001 0.001"/>
      </geometry>
    </collision>
    <contact_coefficients kd="1.0" kp="1000.0" mu="0"/>
  </link>
  <gazebo reference="upper_gripper_finger_left">
    <material>Gazebo/Blue</material>
    <turnGravityOff>false</turnGravityOff>
  </gazebo>
  <!-- GRIPPER RIGHT -->
  <joint name="upper_gripper_finger_right_joint" type="prismatic">
    <limit effort="1.0" lower="0.0027" upper="0.055" velocity="1.0"/>
    <origin rpy="0 0 3.14159" xyz="0 0 0"/>
    <parent link="upper_gripper_base_link"/>
    <child link="upper_gripper_gripper_right"/>
    <axis xyz="-1 0 0"/>
    <dynamics damping="100" friction="100"/>
    <limit effort="100" velocity="100"/>
  </joint>
  <transmission name="upper_gripper_base_trans_right" type="pr2_mechanism_model/SimpleTransmission">
    <actuator name="upper_gripper_base_motor_right"/>
    <joint name="upper_gripper_base_joint_gripper_right"/>
    <mechanicalReduction>1</mechanicalReduction>
    <motorTorqueConstant>1</motorTorqueConstant>
  </transmission>
  <link name="upper_gripper_gripper_right">
    <inertial>
      <mass value="0.1"/>
      <origin xyz="0 0 0"/>
      <inertia ixx="1.0" ixy="0.0" ixz="0.0" iyy="1.0" iyz="0.0" izz="1.0"/>
    </inertial>
    <visual>
      <origin rpy="3.14 0 0" xyz="0.0 0 0"/>
      <geometry>
        <mesh filename="package://wsg_50_simulation/meshes/GUIDE_WSG50_110.stl" scale="0.001 0.001 0.001"/>
        <!--box size="0.0175 0.03 0.024"/-->
      </geometry>
      <material name="black">
        <color rgba="0 0 0 1"/>
      </material>
    </visual>
    <collision>
      <origin rpy="3.14 0 0" xyz="0 0 0"/>
      <geometry>
        <!--box size="0.0175 0.03 0.024"/-->
        <mesh filename="package://wsg_50_simulation/meshes/GUIDE_WSG50_110.stl" scale="0.001 0.001 0.001"/>
      </geometry>
    </collision>
    <contact_coefficients kd="1.0" kp="1000.0" mu="0"/>
  </link>
  <gazebo reference="gripper_right">
    <material>Gazebo/White</material>
    <turnGravityOff>false</turnGravityOff>
  </gazebo>
  <!-- RIGHT FINGER -->
  <joint name="upper_gripper_guide_joint_finger_right" type="fixed">
    <origin rpy="0 0 0" xyz="0 0 -0.017"/>
    <parent link="upper_gripper_gripper_right"/>
    <child link="upper_gripper_finger_right"/>
    <dynamics damping="100" friction="100"/>
    <axis xyz="1 0 0"/>
    <limit effort="100" velocity="100"/>
  </joint>
  <link name="upper_gripper_finger_right">
    <inertial>
      <mass value="0.1"/>
      <origin xyz="0 0 0"/>
      <inertia ixx="1.0" ixy="0.0" ixz="0.0" iyy="1.0" iyz="0.0" izz="1.0"/>
    </inertial>
    <visual>
      <origin rpy="3.14 0 0" xyz="0.0 0 0"/>
      <geometry>
        <mesh filename="package://wsg_50_simulation/meshes/WSG-FMF.stl" scale="0.001 0.001 0.001"/>
      </geometry>
      <material name="black">
        <color rgba="0 0 0 1"/>
      </material>
    </visual>
    <collision>
      <origin rpy="3.14 0 0" xyz="0 0 0"/>
      <geometry>
        <mesh filename="package://wsg_50_simulation/meshes/WSG-FMF.stl" scale="0.001 0.001 0.001"/>
      </geometry>
    </collision>
    <contact_coefficients kd="1.0" kp="1000.0" mu="0"/>
  </link>
  <gazebo reference="upper_gripper_finger_right">
    <material>Gazebo/White</material>
    <turnGravityOff>false</turnGravityOff>
  </gazebo>
  <!-- Fix duaro to world -->
  <link name="world"/>
  <joint name="world2base" type="fixed">
    <parent link="world"/>
    <child link="duarobase_link"/>
    <origin rpy="0 0 0" xyz="0 0 0"/>
  </joint>
</robot>
