<?xml version="1.0" ?>
<!-- =================================================================================== -->
<!-- |    This document was autogenerated by xacro from duaro.urdf.xacro               | -->
<!-- |    EDITING THIS FILE BY HAND IS NOT RECOMMENDED                                 | -->
<!-- =================================================================================== -->
<robot name="khi_duaro">
  <transmission name="lower_join1_trans">
    <type>transmission_interface/SimpleTransmission</type>
    <actuator name="lower_joint1_motor">
      <hardwareInterface>hardware_interface/PositionJointInterface</hardwareInterface>
      <mechanicalReduction>1</mechanicalReduction>
    </actuator>
    <joint name="lower_joint1">
      <hardwareInterface>hardware_interface/PositionJointInterface</hardwareInterface>
    </joint>
  </transmission>
  <transmission name="lower_join2_trans">
    <type>transmission_interface/SimpleTransmission</type>
    <actuator name="lower_joint2_motor">
      <hardwareInterface>hardware_interface/PositionJointInterface</hardwareInterface>
      <mechanicalReduction>1</mechanicalReduction>
    </actuator>
    <joint name="lower_joint2">
      <hardwareInterface>hardware_interface/PositionJointInterface</hardwareInterface>
    </joint>
  </transmission>
  <transmission name="lower_join3_trans">
    <type>transmission_interface/SimpleTransmission</type>
    <actuator name="lower_joint3_motor">
      <hardwareInterface>hardware_interface/PositionJointInterface</hardwareInterface>
      <mechanicalReduction>1</mechanicalReduction>
    </actuator>
    <joint name="lower_joint3">
      <hardwareInterface>hardware_interface/PositionJointInterface</hardwareInterface>
    </joint>
  </transmission>
  <transmission name="lower_join4_trans">
    <type>transmission_interface/SimpleTransmission</type>
    <actuator name="lower_joint4_motor">
      <hardwareInterface>hardware_interface/PositionJointInterface</hardwareInterface>
      <mechanicalReduction>1</mechanicalReduction>
    </actuator>
    <joint name="lower_joint4">
      <hardwareInterface>hardware_interface/PositionJointInterface</hardwareInterface>
    </joint>
  </transmission>
  <transmission name="upper_join1_trans">
    <type>transmission_interface/SimpleTransmission</type>
    <actuator name="upper_joint1_motor">
      <hardwareInterface>hardware_interface/PositionJointInterface</hardwareInterface>
      <mechanicalReduction>1</mechanicalReduction>
    </actuator>
    <joint name="upper_joint1">
      <hardwareInterface>hardware_interface/PositionJointInterface</hardwareInterface>
    </joint>
  </transmission>
  <transmission name="upper_join2_trans">
    <type>transmission_interface/SimpleTransmission</type>
    <actuator name="upper_joint2_motor">
      <hardwareInterface>hardware_interface/PositionJointInterface</hardwareInterface>
      <mechanicalReduction>1</mechanicalReduction>
    </actuator>
    <joint name="upper_joint2">
      <hardwareInterface>hardware_interface/PositionJointInterface</hardwareInterface>
    </joint>
  </transmission>
  <transmission name="upper_join3_trans">
    <type>transmission_interface/SimpleTransmission</type>
    <actuator name="upper_joint3_motor">
      <hardwareInterface>hardware_interface/PositionJointInterface</hardwareInterface>
      <mechanicalReduction>1</mechanicalReduction>
    </actuator>
    <joint name="upper_joint3">
      <hardwareInterface>hardware_interface/PositionJointInterface</hardwareInterface>
    </joint>
  </transmission>
  <transmission name="upper_join4_trans">
    <type>transmission_interface/SimpleTransmission</type>
    <actuator name="upper_joint4_motor">
      <hardwareInterface>hardware_interface/PositionJointInterface</hardwareInterface>
      <mechanicalReduction>1</mechanicalReduction>
    </actuator>
    <joint name="upper_joint4">
      <hardwareInterface>hardware_interface/PositionJointInterface</hardwareInterface>
    </joint>
  </transmission>
  <!-- link rviz color-->
  <material name="Light_blue">
    <color rgba="0 1.0 1.0 1.0"/>
  </material>
  <material name="White">
    <color rgba="1.0 1.0 1.0 1.0"/>
  </material>
  <material name="Black">
    <color rgba="0 0 0 1.0"/>
  </material>
  <material name="Red">
    <color rgba="1.0 0 0 1.0"/>
  </material>
  <link name="base_link">
    <visual>
      <geometry>
        <mesh filename="package://khi_duaro_description/meshes/WD002N_F502_Adjuster_pad.stl"/>
      </geometry>
      <material name="White"/>
      <origin rpy="0 0 0" xyz="0 0 0"/>
    </visual>
    <collision>
      <geometry>
        <mesh filename="package://khi_duaro_description/meshes/WD002N_F502_Adjuster_pad.stl"/>
      </geometry>
      <material name="White"/>
      <origin rpy="0 0 0" xyz="0 0 0"/>
    </collision>
  </link>
  <link name="duaro_body">
    <visual>
      <geometry>
        <mesh filename="package://khi_duaro_description/meshes/WD002N_F502_Cabinet_body.stl"/>
      </geometry>
      <material name="White"/>
      <origin rpy="0 0 0" xyz="0 0 0"/>
    </visual>
    <collision>
      <geometry>
        <mesh filename="package://khi_duaro_description/meshes/WD002N_F502_Cabinet_body.stl"/>
      </geometry>
      <origin rpy="0 0 0" xyz="0 0 0"/>
    </collision>
    <inertial>
      <mass value="100"/>
      <inertia ixx="1.0" ixy="0.0" ixz="0.0" iyy="1.0" iyz="0.0" izz="1.0"/>
    </inertial>
  </link>
  <joint name="duaro_body_joint" type="fixed">
    <parent link="base_link"/>
    <child link="duaro_body"/>
    <origin rpy="0 0 0" xyz="0 0 0"/>
  </joint>
  <link name="duaro_j0_cover">
    <visual>
      <geometry>
        <mesh filename="package://khi_duaro_description/meshes/WD002N_A201_j0_cover_Ver2m.stl"/>
      </geometry>
      <material name="Light_blue"/>
      <origin rpy="0 0 0" xyz="0 0 0"/>
    </visual>
    <collision>
      <geometry>
        <mesh filename="package://khi_duaro_description/meshes/WD002N_A201_j0_cover_Ver2m.stl"/>
      </geometry>
      <origin rpy="0 0 0" xyz="0 0 0"/>
    </collision>
    <inertial>
      <mass value="2"/>
      <inertia ixx="1.0" ixy="0.0" ixz="0.0" iyy="1.0" iyz="0.0" izz="1.0"/>
    </inertial>
  </link>
  <joint name="duaro_j0_cover_joint" type="fixed">
    <parent link="base_link"/>
    <child link="duaro_j0_cover"/>
    <origin rpy="0 0 0" xyz="0 0 0.82"/>
  </joint>
  <link name="duaro_logo">
    <visual>
      <geometry>
        <mesh filename="package://khi_duaro_description/meshes/WD002N_F502_LOGO_duAro.stl"/>
      </geometry>
      <material name="Black"/>
      <origin rpy="0 0 0" xyz="0 0 0"/>
    </visual>
    <collision>
      <geometry>
        <mesh filename="package://khi_duaro_description/meshes/WD002N_F502_LOGO_duAro.stl"/>
      </geometry>
      <origin rpy="0 0 0" xyz="0 0 0"/>
    </collision>
    <inertial>
      <mass value="1"/>
      <inertia ixx="1.0" ixy="0.0" ixz="0.0" iyy="1.0" iyz="0.0" izz="1.0"/>
    </inertial>
  </link>
  <joint name="duaro_logo_joint" type="fixed">
    <parent link="base_link"/>
    <child link="duaro_logo"/>
    <origin rpy="0 0 0" xyz="0 0 0"/>
  </joint>
  <link name="kawasaki_logo">
    <visual>
      <geometry>
        <mesh filename="package://khi_duaro_description/meshes/WD002N_F502_LOGO_Kawasaki.stl"/>
      </geometry>
      <material name="Red"/>
      <origin rpy="0 0 0" xyz="0 0 0"/>
    </visual>
    <collision>
      <geometry>
        <mesh filename="package://khi_duaro_description/meshes/WD002N_F502_LOGO_Kawasaki.stl"/>
      </geometry>
      <origin rpy="0 0 0" xyz="0 0 0"/>
    </collision>
    <inertial>
      <mass value="1"/>
      <inertia ixx="1.0" ixy="0.0" ixz="0.0" iyy="1.0" iyz="0.0" izz="1.0"/>
    </inertial>
  </link>
  <joint name="kawasaki_logo_joint" type="fixed">
    <parent link="base_link"/>
    <child link="kawasaki_logo"/>
    <origin rpy="0 0 0" xyz="0 0 0"/>
  </joint>
  <link name="duaro_body_cover">
    <visual>
      <geometry>
        <mesh filename="package://khi_duaro_description/meshes/WD002N_F502_Cabinet_front_cover.stl"/>
      </geometry>
      <material name="Light_blue"/>
      <origin rpy="0 0 0" xyz="0 0 0"/>
    </visual>
    <collision>
      <geometry>
        <mesh filename="package://khi_duaro_description/meshes/WD002N_F502_Cabinet_front_cover.stl"/>
      </geometry>
      <origin rpy="0 0 0" xyz="0 0 0"/>
    </collision>
    <inertial>
      <mass value="1"/>
      <inertia ixx="1.0" ixy="0.0" ixz="0.0" iyy="1.0" iyz="0.0" izz="1.0"/>
    </inertial>
  </link>
  <joint name="duaro_body_cover_joint" type="fixed">
    <parent link="base_link"/>
    <child link="duaro_body_cover"/>
    <origin rpy="0 0 0" xyz="0 0 0"/>
  </joint>
  <link name="cart">
    <visual>
      <geometry>
        <mesh filename="package://khi_duaro_description/meshes/WD002N_F502_Cart.stl"/>
      </geometry>
      <material name="White"/>
      <origin rpy="0 0 0" xyz="0 0 0"/>
    </visual>
    <collision>
      <geometry>
        <mesh filename="package://khi_duaro_description/meshes/WD002N_F502_Cart.stl"/>
      </geometry>
      <origin rpy="0 0 0" xyz="0 0 0"/>
    </collision>
    <inertial>
      <mass value="2"/>
      <inertia ixx="1.0" ixy="0.0" ixz="0.0" iyy="1.0" iyz="0.0" izz="1.0"/>
    </inertial>
  </link>
  <joint name="cart_joint" type="fixed">
    <parent link="base_link"/>
    <child link="cart"/>
    <origin rpy="0 0 0" xyz="0 0 0"/>
  </joint>
  <link name="duaro_j0">
    <visual>
      <geometry>
        <mesh filename="package://khi_duaro_description/meshes/WD002N_A201_j0_Ver2m.stl"/>
      </geometry>
      <material name="White"/>
      <origin rpy="0 0 0" xyz="0 0 0"/>
    </visual>
    <collision>
      <geometry>
        <mesh filename="package://khi_duaro_description/meshes/WD002N_A201_j0_Ver2m.stl"/>
      </geometry>
      <origin rpy="0 0 0" xyz="0 0 0"/>
    </collision>
    <inertial>
      <mass value="10"/>
      <inertia ixx="1.0" ixy="0.0" ixz="0.0" iyy="1.0" iyz="0.0" izz="1.0"/>
    </inertial>
  </link>
  <joint name="joint0" type="fixed">
    <origin xyz="0 0 0.82"/>
    <parent link="duaro_body"/>
    <child link="duaro_j0"/>
  </joint>
  <!-- lower arm -->
  <link name="lower_link_j1">
    <visual>
      <geometry>
        <mesh filename="package://khi_duaro_description/meshes/WD002N_A201L_J1_Ver2m.stl"/>
      </geometry>
      <material name="White"/>
      <origin rpy="0 0 0" xyz="0 0 0"/>
    </visual>
    <collision>
      <geometry>
        <mesh filename="package://khi_duaro_description/meshes/WD002N_A201L_J1_Ver2m.stl"/>
      </geometry>
      <material name="White"/>
      <origin rpy="0 0 0" xyz="0 0 0"/>
    </collision>
    <inertial>
      <mass value="11.463"/>
      <inertia ixx="1.0" ixy="0.0" ixz="0.0" iyy="1.0" iyz="0.0" izz="0.806914299802127"/>
    </inertial>
  </link>
  <joint name="lower_joint1" type="revolute">
    <axis rpy="0 0 0" xyz="0 0 1"/>
    <limit effort="100.0" lower="-2.9670597283903604" upper="2.9670597283903604" velocity="4.1887902047863905"/>
    <origin rpy="0 0 0" xyz="0 0 0.2515"/>
    <parent link="duaro_j0"/>
    <child link="lower_link_j1"/>
    <dynamics damping="0.0" friction="0.0"/>
  </joint>
  <link name="lower_link_j2">
    <visual>
      <geometry>
        <mesh filename="package://khi_duaro_description/meshes/WD002N_A202L_J2m.stl"/>
      </geometry>
      <material name="White"/>
      <origin rpy="0 0 0" xyz="0 0 0"/>
    </visual>
    <collision>
      <geometry>
        <mesh filename="package://khi_duaro_description/meshes/WD002N_A202L_J2m.stl"/>
      </geometry>
      <material name="White"/>
      <origin rpy="0 0 0" xyz="0 0 0"/>
    </collision>
    <inertial>
      <mass value="3.747"/>
      <inertia ixx="1.0" ixy="0.0" ixz="0.0" iyy="1.0" iyz="0.0" izz="0.167113962990643"/>
    </inertial>
  </link>
  <joint name="lower_joint2" type="revolute">
    <axis rpy="0 0 0" xyz="0 0 1"/>
    <limit effort="100.0" lower="-2.443460952792061" upper="2.443460952792061" velocity="5.497787143782138"/>
    <origin xyz="0 0.36 0.0905"/>
    <parent link="lower_link_j1"/>
    <child link="lower_link_j2"/>
    <dynamics damping="0.0" friction="0.0"/>
  </joint>
  <link name="lower_link_j3">
    <visual>
      <geometry>
        <mesh filename="package://khi_duaro_description/meshes/WD002N_A202L_J3m.stl"/>
      </geometry>
      <material name="White"/>
      <origin rpy="0 0 0" xyz="0 0 0"/>
    </visual>
    <collision>
      <geometry>
        <mesh filename="package://khi_duaro_description/meshes/WD002N_A202L_J3m.stl"/>
      </geometry>
      <material name="White"/>
      <origin rpy="0 0 0" xyz="0 0 0"/>
    </collision>
    <inertial>
      <mass value="3.476"/>
      <inertia ixx="1.0" ixy="0.0" ixz="0.0" iyy="1.0" iyz="0.0" izz="1.0"/>
    </inertial>
  </link>
  <joint name="lower_joint3" type="prismatic">
    <axis rpy="0 0 0" xyz="0 0 1"/>
    <limit effort="100.0" lower="0" upper="0.15" velocity="0.3"/>
    <origin xyz="0 0.4 0.03850"/>
    <parent link="lower_link_j2"/>
    <child link="lower_link_j3"/>
  </joint>
  <link name="lower_link_j3_obst">
    <visual>
      <geometry>
        <mesh filename="package://khi_duaro_description/meshes/WD002N_A202L_J3_obstaclem.stl"/>
      </geometry>
      <material name="Black"/>
      <origin rpy="0 0 0" xyz="0 0 0"/>
    </visual>
  </link>
  <joint name="lower_j3_obstaclem_joint" type="fixed">
    <origin rpy="0 0 0" xyz="0 0 0"/>
    <parent link="lower_link_j3"/>
    <child link="lower_link_j3_obst"/>
  </joint>
  <link name="lower_link_j4">
    <visual>
      <geometry>
        <mesh filename="package://khi_duaro_description/meshes/WD002N_A202L_J4m.stl"/>
      </geometry>
      <material name=""/>
      <origin rpy="0 0 0" xyz="0 0 0"/>
    </visual>
    <collision>
      <geometry>
        <mesh filename="package://khi_duaro_description/meshes/WD002N_A202L_J4m.stl"/>
      </geometry>
      <material name="White"/>
      <origin rpy="0 0 0" xyz="0 0 0"/>
    </collision>
    <inertial>
      <mass value="0.5"/>
      <inertia ixx="1.0" ixy="0.0" ixz="0.0" iyy="1.0" iyz="0.0" izz="1.0"/>
    </inertial>
  </link>
  <joint name="lower_joint4" type="revolute">
    <axis rpy="0 0 0" xyz="0 0 1"/>
    <limit effort="100.0" lower="-6.283185307179586" upper="6.283185307179586" velocity="10.471975511965978"/>
    <origin xyz="0 0 -0.24"/>
    <parent link="lower_link_j3"/>
    <child link="lower_link_j4"/>
    <dynamics damping="0.0" friction="0.0"/>
  </joint>
  <!-- upper arm -->
  <link name="upper_link_j1">
    <visual>
      <geometry>
        <mesh filename="package://khi_duaro_description/meshes/WD002N_A201U_J1_Ver2m.stl"/>
      </geometry>
      <material name="White"/>
      <origin xyz="0 0 0"/>
    </visual>
    <collision>
      <geometry>
        <mesh filename="package://khi_duaro_description/meshes/WD002N_A201U_J1_Ver2m.stl"/>
      </geometry>
      <material name="White"/>
      <origin rpy="0 0 0" xyz="0 0 0"/>
    </collision>
    <inertial>
      <mass value="11.452"/>
      <inertia ixx="1.0" ixy="0.0" ixz="0.0" iyy="1.0" iyz="0.0" izz="0.8539434419510881"/>
    </inertial>
  </link>
  <joint name="upper_joint1" type="revolute">
    <origin rpy="0 0 0" xyz="0 0 0.3805"/>
    <axis rpy="0 0 0" xyz="0 0 1"/>
    <limit effort="100.0" lower="-2.443460952792061" upper="8.726646259971648" velocity="4.1887902047863905"/>
    <parent link="duaro_j0"/>
    <child link="upper_link_j1"/>
    <dynamics damping="0.0" friction="0.0"/>
  </joint>
  <link name="upper_link_j2">
    <visual>
      <geometry>
        <mesh filename="package://khi_duaro_description/meshes/WD002N_A202U_J2m.stl"/>
      </geometry>
      <material name="White"/>
      <origin rpy="0 0 0" xyz="0 0 0"/>
    </visual>
    <collision>
      <geometry>
        <mesh filename="package://khi_duaro_description/meshes/WD002N_A202U_J2m.stl"/>
      </geometry>
      <material name="White"/>
      <origin rpy="0 0 0" xyz="0 0 0"/>
    </collision>
    <inertial>
      <mass value="3.751"/>
      <inertia ixx="1.0" ixy="0.0" ixz="0.0" iyy="1.0" iyz="0.0" izz="0.167279751763904"/>
    </inertial>
  </link>
  <joint name="upper_joint2" type="revolute">
    <axis rpy="0 0 0" xyz="0 0 1"/>
    <limit effort="100.0" lower="-2.443460952792061" upper="2.443460952792061" velocity="5.497787143782138"/>
    <origin xyz="0 0.36 0"/>
    <parent link="upper_link_j1"/>
    <child link="upper_link_j2"/>
    <dynamics damping="0.0" friction="0.0"/>
  </joint>
  <link name="upper_link_j3">
    <visual>
      <geometry>
        <mesh filename="package://khi_duaro_description/meshes/WD002N_A202U_J3m.stl"/>
      </geometry>
      <material name="White"/>
      <origin rpy="0 0 0" xyz="0 0 0"/>
    </visual>
    <collision>
      <geometry>
        <mesh filename="package://khi_duaro_description/meshes/WD002N_A202U_J3m.stl"/>
      </geometry>
      <material name="White"/>
      <origin rpy="0 0 0" xyz="0 0 0"/>
    </collision>
    <inertial>
      <mass value="3.476"/>
      <inertia ixx="1.0" ixy="0.0" ixz="0.0" iyy="1.0" iyz="0.0" izz="1.0"/>
    </inertial>
  </link>
  <joint name="upper_joint3" type="prismatic">
    <axis rpy="0 0 0" xyz="0 0 1"/>
    <limit effort="100.0" lower="0" upper="0.15" velocity="0.3"/>
    <origin xyz="0 0.4 0"/>
    <parent link="upper_link_j2"/>
    <child link="upper_link_j3"/>
  </joint>
  <link name="upper_link_j3_obst">
    <visual>
      <geometry>
        <mesh filename="package://khi_duaro_description/meshes/WD002N_A202U_J3_obstaclem.stl"/>
      </geometry>
      <material name="Black"/>
      <origin rpy="0 0 0" xyz="0 0 0"/>
    </visual>
  </link>
  <joint name="upper_j3_obstaclem_joint" type="fixed">
    <origin xyz="0 0 0"/>
    <parent link="upper_link_j3"/>
    <child link="upper_link_j3_obst"/>
  </joint>
  <link name="upper_link_j4">
    <visual>
      <geometry>
        <mesh filename="package://khi_duaro_description/meshes/WD002N_A202U_J4m.stl"/>
      </geometry>
      <material name=""/>
      <origin rpy="0 0 0" xyz="0 0 0"/>
    </visual>
    <collision>
      <geometry>
        <mesh filename="package://khi_duaro_description/meshes/WD002N_A202U_J4m.stl"/>
      </geometry>
      <material name="White"/>
      <origin rpy="0 0 0" xyz="0 0 0"/>
    </collision>
    <inertial>
      <mass value="10"/>
      <inertia ixx="1.0" ixy="0.0" ixz="0.0" iyy="1.0" iyz="0.0" izz="1.0"/>
    </inertial>
  </link>
  <joint name="upper_joint4" type="revolute">
    <axis rpy="0 0 0" xyz="0 0 1"/>
    <limit effort="100.0" lower="-6.283185307179586" upper="6.283185307179586" velocity="0.3"/>
    <origin xyz="0 0 -0.24"/>
    <parent link="upper_link_j3"/>
    <child link="upper_link_j4"/>
    <dynamics damping="0.0" friction="0.0"/>
  </joint>
  <gazebo reference="duaro_body">
    <material>Gazebo/White</material>
  </gazebo>
  <gazebo reference="pedestal_obstacle">
    <material>Gazebo/Light_blue</material>
  </gazebo>
  <gazebo reference="duaro_logo">
    <material>Gazebo/Black</material>
  </gazebo>
  <gazebo reference="base_link">
    <material>Gazebo/White</material>
  </gazebo>
  <gazebo reference="duaro_j0">
    <material>Gazebo/White</material>
  </gazebo>
  <gazebo reference="duaro_j0_cover">
    <material>Gazebo/Light_blue</material>
  </gazebo>
  <gazebo reference="lower_link_j1">
    <material>Gazebo/White</material>
  </gazebo>
  <gazebo reference="lower_link_j2">
    <material>Gazebo/White</material>
  </gazebo>
  <gazebo reference="lower_link_j3">
    <material>Gazebo/White</material>
  </gazebo>
  <gazebo reference="lower_link_j4">
    <material>Gazebo/White</material>
  </gazebo>
  <gazebo reference="lower_link_j3_obst">
    <material>Gazebo/Black</material>
  </gazebo>
  <gazebo reference="upper_link_j1">
    <material>Gazebo/White</material>
  </gazebo>
  <gazebo reference="upper_link_j2">
    <material>Gazebo/White</material>
  </gazebo>
  <gazebo reference="upper_link_j3">
    <material>Gazebo/White</material>
  </gazebo>
  <gazebo reference="upper_link_j4">
    <material>Gazebo/White</material>
  </gazebo>
  <gazebo reference="upper_link_j3_obst">
    <material>Gazebo/Black</material>
  </gazebo>
  <gazebo reference="duaro_body">
    <material>Gazebo/White</material>
  </gazebo>
  <!-- duaro end -->
  <gazebo>
    <plugin filename="libgazebo_ros_control.so" name="gazebo_ros_control">
      <robotNamespace>/</robotNamespace>
    </plugin>
  </gazebo>
  <!-- Fix duaro to world -->
  <link name="world"/>
  <joint name="world2base" type="fixed">
    <parent link="world"/>
    <child link="base_link"/>
    <origin rpy="0 0 0" xyz="0 0 0"/>
  </joint>
</robot>

